Workbook

Sheet Inventario 2026
A1: ID | B1: DESCRIPCION | C1: REFERENCIA | D1: SUB-GRUPO DE ARTICULO | E1: EXISTENCIA | F1: COSTO | G1: PRECIO DETALLE | H1: VALOR COSTO | I1: VALOR VENTA
A2: 1001 | B2: D3 K2 Walnut Oil Drops - Lecrano - 60 ml | C2: 1001 | D2: Suplementos | E2: 15 | F2: 516 | G2: 1500 | H2: =E2*F2 -> 7740 | I2: =E2*G2 -> 22500
A3: 1002 | B3: Tribulus 1400 - Nutrex - 90 cápsulas | C3: 1002 | D3: Suplementos | E3: 6 | F3: 850 | G3: 1500 | H3: =E3*F3 -> 5100 | I3: =E3*G3 -> 9000
A4: 1003 | B4: Opti-Men - Optimum Nutrition - 150 tabletas / 50 servicios | C4: 1003 | D4: Suplementos | E4: 3 | F4: 1000 | G4: 2450 | H4: =E4*F4 -> 3000 | I4: =E4*G4 -> 7350
A5: 1004 | B5: Opti-Men - Optimum Nutrition - 90 tabletas / 30 servicios | C5: 1004 | D5: Suplementos | E5: 2 | F5: 1250 | G5: 1950 | H5: =E5*F5 -> 2500 | I5: =E5*G5 -> 3900
A6: 1005 | B6: Opti-Men - Optimum Nutrition - 240 tabletas / 80 servicios | C6: 1005 | D6: Suplementos | E6: 14 | F6: 1400 | G6: 2900 | H6: =E6*F6 -> 19600 | I6: =E6*G6 -> 40600
A7: 1006 | B7: Essential Digestive Enzymes - Horbäach - 1000 mg / 100 cápsulas | C7: 1006 | D7: Suplementos | E7: 7 | F7: 800 | G7: 1500 | H7: =E7*F7 -> 5600 | I7: =E7*G7 -> 10500
A8: 1007 | B8: Horny Goat Weed - dr.bo. - 60 cápsulas | C8: 1007 | D8: Suplementos | E8: 3 | F8: 900 | G8: 1600 | H8: =E8*F8 -> 2700 | I8: =E8*G8 -> 4800
A9: 1008 | B9: Oil of Oregano - Carlyle - 4000 mg equivalentes / 150 softgels | C9: 1008 | D9: Suplementos | E9: 4 | F9: 740 | G9: 1500 | H9: =E9*F9 -> 2960 | I9: =E9*G9 -> 6000
A10: 1009 | B10: Garlic Oil - Puritan's Pride - 5000 mg | C10: 1009 | D10: Suplementos | E10: 1 | F10: 900 | G10: 1500 | H10: =E10*F10 -> 900 | I10: =E10*G10 -> 1500
A11: 1010 | B11: Chromium Picolinate - Horbäach - 1000 mcg / 240 tabletas | C11: 1010 | D11: Suplementos | E11: 3 | F11: 800 | G11: 1500 | H11: =E11*F11 -> 2400 | I11: =E11*G11 -> 4500
A12: 1011 | B12: Testosterone Booster - Six Star - 60 caplets | C12: 1011 | D12: Suplementos | E12: 6 | F12: 750 | G12: 1500 | H12: =E12*F12 -> 4500 | I12: =E12*G12 -> 9000
A13: 1012 | B13: L-Carnitine 3000 - Nutrex - Strawberry Watermelon / 31 serv. | C13: 1012 | D13: Suplementos | E13: 2 | F13: 775 | G13: 1450 | H13: =E13*F13 -> 1550 | I13: =E13*G13 -> 2900
... A617: 1616 | B617: Faja tipo chaleco M | C617: 1616 | D617: Fajas | E617: 2 | F617: 1500 | G617: 3500 | H617: =E617*F617 -> 3000 | I617: =E617*G617 -> 7000
A619: =COUNTA(A2:A617) -> 616 | D619: TOTAL | E619: =SUM(E2:E617) -> 3158 | H619: =SUM(H2:H617) -> 2220851 | I619: =SUM(I2:I617) -> 4590005

Sheet Resumen
A1: Sub-grupo | B1: Productos | C1: Con existencia | D1: Unidades | E1: Valor costo | F1: Valor venta
A2: Suplementos | B2: =COUNTIF('Inventario 2026'!$D$2:$D$617,A2) -> 221 | C2: =COUNTIFS('Inventario 2026'!$D$2:$D$617,A2,'Inventario 2026'!$E$2:$E$617,">0") -> 214 | D2: =SUMIF('Inventario 2026'!$D$2:$D$617,A2,'Inventario 2026'!$E$2:$E$617) -> 910 | E2: =SUMIF('Inventario 2026'!$D$2:$D$617,A2,'Inventario 2026'!$H$2:$H$617) -> 1098035 | F2: =SUMIF('Inventario 2026'!$D$2:$D$617,A2,'Inventario 2026'!$I$2:$I$617) -> 2033920
A3: Maquillaje | B3: =COUNTIF('Inventario 2026'!$D$2:$D$617,A3) -> 355 | C3: =COUNTIFS('Inventario 2026'!$D$2:$D$617,A3,'Inventario 2026'!$E$2:$E$617,">0") -> 351 | D3: =SUMIF('Inventario 2026'!$D$2:$D$617,A3,'Inventario 2026'!$E$2:$E$617) -> 2062 | E3: =SUMIF('Inventario 2026'!$D$2:$D$617,A3,'Inventario 2026'!$H$2:$H$617) -> 861116 | F3: =SUMIF('Inventario 2026'!$D$2:$D$617,A3,'Inventario 2026'!$I$2:$I$617) -> 1985985
A4: Fajas | B4: =COUNTIF('Inventario 2026'!$D$2:$D$617,A4) -> 40 | C4: =COUNTIFS('Inventario 2026'!$D$2:$D$617,A4,'Inventario 2026'!$E$2:$E$617,">0") -> 36 | D4: =SUMIF('Inventario 2026'!$D$2:$D$617,A4,'Inventario 2026'!$E$2:$E$617) -> 186 | E4: =SUMIF('Inventario 2026'!$D$2:$D$617,A4,'Inventario 2026'!$H$2:$H$617) -> 261700 | F4: =SUMIF('Inventario 2026'!$D$2:$D$617,A4,'Inventario 2026'!$I$2:$I$617) -> 570100
A5: TOTAL | B5: =SUM(B2:B4) -> 616 | C5: =SUM(C2:C4) -> 601 | D5: =SUM(D2:D4) -> 3158 | E5: =SUM(E2:E4) -> 2220851 | F5: =SUM(F2:F4) -> 4590005

Sheet Cambios
A1: Paso | B1: ID | C1: Nombre anterior | D1: Nombre nuevo | E1: Existencia anterior | F1: Existencia nueva | G1: Nota
A2: 1 - Makeup | B2: 1223 | C2: PRO.CONCEAL HD HIGH-DEFINITION CONCEALER - L.A. GIRL - GC983 FAWN | BARCODE 081555969837 | D2: L.A. Girl PRO.conceal HD High-Definition Concealer GC983 Fawn | Barcode 081555969837 | E2: 23 | F2: 24 | G2: Existencia actualizada
A3: 1 - Makeup | B3: 1231 | C3: SOFT FOCUS WATERPROOF SETTING POWDER - 11.5 G - MOIRA - 200 | D3: MOIRA Soft Focus Waterproof Setting Powder – 11.5 g 200 | E3: 6 | F3: 7 | G3: Existencia actualizada
A4: 1 - Makeup | B4: 1232 | C4: SOFT FOCUS WATERPROOF SETTING POWDER - 11.5 G - MOIRA - 250 | D4: MOIRA Soft Focus Waterproof Setting Powder – 11.5 g 250 | E4: 4 | F4: 5 | G4: Existencia actualizada
A5: 1 - Makeup | B5: 1233 | C5: SOFT FOCUS WATERPROOF SETTING POWDER - 11.5 G - MOIRA - 350 | D5: MOIRA Soft Focus Waterproof Setting Powder – 11.5 g 350 | E5: 6 | F5: 7 | G5: Existencia actualizada
A6: 1 - Makeup | B6: 1263 | C6: BEAUTY BLENDER - COLOR CREMA | D6: Sin marca Beauty Blender Color crema | E6: 43 | F6: 47 | G6: Existencia actualizada
A7: 1 - Makeup | B7: 1350 | C7: GLOSS - AMUSE - SPICE | D7: Amuse Gloss Spice | E7: 2 | F7: 3 | G7: Existencia actualizada
A8: 1 - Makeup | B8: 1374 | C8: ULTRA PRECISE EYEBROW PENCIL - MISSLYN - 01 | D8: Misslyn Ultra Precise Eyebrow Pencil 01 | E8: 1 | F8: 2 | G8: Existencia actualizada
A9: 1 - Makeup | B9: 1411 | C9: JABÓN FIJADOR PARA CEJAS - PEARS | D9: Pears Jabón fijador para cejas | E9: 9 | F9: 10 | G9: Existencia actualizada
A10: 1 - Makeup | B10: 1445 | C10: LIQUID FOUNDATION - AMAVÉ - 04 | D10: Amave Liquid Foundation 04 | E10: 20 | F10: 21 | G10: Existencia actualizada
A11: 1 - Makeup | B11: 1446 | C11: LIQUID FOUNDATION - AMAVÉ - 07 | D11: Amave Liquid Foundation 07 | E11: 8 | F11: 5 | G11: Existencia actualizada
A12: 1 - Makeup | B12: 1447 | C12: LIQUID FOUNDATION - AMAVÉ - 02 | D12: Amave Liquid Foundation 02 | E12: 1 | F12: 7 | G12: Existencia actualizada
A13: 1 - Makeup | B13: 1448 | C13: LIQUID FOUNDATION - AMAVÉ - 03 | D13: Amave Liquid Foundation 03 | E13: 7 | F13: 16 | G13: Existencia actualizada
... A37: 1 - Makeup | B37: 1528 | C37: INFALLIBLE FULL WEAR CONCEALER - LORÉAL PARIS - 330 | D37: L'Oréal Paris Infallible Full Wear Concealer 330 | E37: 17 | F37: 18 | G37: Existencia actualizada
A38: 1 - Makeup | B38: 1613 | C38: (no existía en la base) | D38: Amave Liquid Foundation 05 | F38: 4 | G38: Producto nuevo — costo y precio tomados de Amave Liquid Foundation 01 (ID 1450)
A39: 1 - Makeup | B39: 1614 | C39: (no existía en la base) | D39: Amave Full Coverage Concealer 04 | F39: 22 | G39: Producto nuevo — costo y precio tomados de Amave Full Coverage Concealer 03 (ID 1451)
A40: 2 - Fajas | B40: 1576 | C40: CINTURILLA TIPO CORSET - 3XS | D40: Cinturilla tipo corset 3XS | E40: 25 | F40: 26 | G40: Existencia actualizada (suma de los 2 bloques del listado: 18 + 8)
A41: 2 - Fajas | B41: 1577 | C41: CINTURILLA TIPO CORSET - S | D41: Cinturilla tipo corset S | E41: 2 | F41: 5 | G41: Existencia actualizada (suma de los 2 bloques del listado: 2 + 3)
A42: 2 - Fajas | B42: 1590 | C42: PANTY NEGRO - XS / RESALTA GLÚTEOS - PANTY DESCADERADO - ENCAJE SILICONADO | D42: Panty Negro XS | E42: 3 | F42: 4 | G42: Existencia actualizada
A43: 2 - Fajas | B43: 1601 | C43: CINTURILLA TIPO CORSET - XS | D43: Cinturilla tipo corset XS | E43: 1 | F43: 3 | G43: Existencia actualizada
A44: 2 - Fajas | B44: 1602 | C44: CINTURILLA TIPO CORSET - L | D44: Cinturilla tipo corset L | E44: 2 | F44: 3 | G44: Existencia actualizada
A45: 2 - Fajas | B45: 1605 | C45: FAJA TIPO CHALECO - XS | D45: Faja tipo chaleco XS | E45: 2 | F45: 4 | G45: Existencia actualizada
A46: 2 - Fajas | B46: 1607 | C46: FAJA TIPO CHALECO - XL | D46: Faja tipo chaleco XL | E46: 0 | F46: 2 | G46: Existencia actualizada
A47: 2 - Fajas | B47: 1615 | C47: (no existía en la base) | D47: Faja tipo chaleco S | F47: 2 | G47: Producto nuevo — costo y precio tomados de Faja tipo chaleco XS (ID 1605)
A48: 2 - Fajas | B48: 1616 | C48: (no existía en la base) | D48: Faja tipo chaleco M | F48: 2 | G48: Producto nuevo — costo y precio tomados de Faja tipo chaleco XS (ID 1605)
A49: 3 - Suplementos | B49: 1002 | C49: TRIBULUS 1400 - NUTREX - 90 CÁPSULAS | D49: Tribulus 1400 - Nutrex - 90 cápsulas | E49: 5 | F49: 6 | G49: Existencia actualizada
A50: 3 - Suplementos | B50: 1003 | C50: OPTI-MEN - OPTIMUM NUTRITION - 150 TABLETAS / 50 SERVICIOS | D50: Opti-Men - Optimum Nutrition - 150 tabletas / 50 servicios | E50: 2 | F50: 3 | G50: Existencia actualizada
A51: 3 - Suplementos | B51: 1012 | C51: L-CARNITINE 3000 - NUTREX - STRAWBERRY WATERMELON / 31 SERV. | D51: L-Carnitine 3000 - Nutrex - Strawberry Watermelon / 31 serv. | E51: 1 | F51: 2 | G51: Existencia actualizada
A52: 3 - Suplementos | B52: 1018 | C52: TESTROL GOLD ES - GAT SPORT - 60 TABLETAS | D52: Testrol Gold ES - GAT Sport - 60 tabletas | E52: 9 | F52: 10 | G52: Existencia actualizada
A53: 3 - Suplementos | B53: 1022 | C53: MAGNESIUM CITRATE - NOW - 120 CÁPSULAS VEGETALES | D53: Magnesium Citrate - NOW - 120 cápsulas vegetales | E53: 1 | F53: 2 | G53: Existencia actualizada
A54: 3 - Suplementos | B54: 1025 | C54: ZINC PICOLINATE - PURITANS PRIDE - 25 MG / 100 CAPLETS | D54: Zinc Picolinate - Puritan's Pride - 25 mg / 100 caplets | E54: 4 | F54: 6 | G54: Existencia actualizada
A55: 3 - Suplementos | B55: 1030 | C55: MAGNESIUM GLYCINATE - PRO PERFORMANCE NUTRITION - 60 CÁPSULAS | D55: Magnesium Glycinate - Pro Performance Nutrition - 60 cápsulas | E55: 1 | F55: 5 | G55: Existencia actualizada
A56: 3 - Suplementos | B56: 1046 | C56: GABA - PURITANS PRIDE - 750 MG / 90 CÁPSULAS | D56: GABA - Puritan's Pride - 750 mg / 90 cápsulas | E56: 3 | F56: 4 | G56: Existencia actualizada
A57: 3 - Suplementos | B57: 1048 | C57: BERBERINE - PURITANS PRIDE - 500 MG / 60 CÁPSULAS VEGETALES | D57: Berberine - Puritan's Pride - 500 mg / 60 cápsulas vegetales | E57: 0 | F57: 1 | G57: Existencia actualizada
A58: 3 - Suplementos | B58: 1062 | C58: FENUGREEK - HORBÄACH - 3000 MG EQUIVALENTES POR SERVICIO / 150 CÁPSULAS | D58: Fenugreek - Horbäach - 3000 mg equivalentes por servicio / 150 cápsulas | E58: 6 | F58: 7 | G58: Existencia actualizada
A59: 3 - Suplementos | B59: 1063 | C59: ASHWAGANDHA - HORBÄACH - 450 MG EXTRACTO 10:1 / 120 CÁPSULAS | D59: Ashwagandha - Horbäach - 450 mg extracto 10:1 / 120 cápsulas | E59: 0 | F59: 1 | G59: Existencia actualizada
A60: 3 - Suplementos | B60: 1076 | C60: MICRONIZED CREATINE POWDER - OPTIMUM NUTRITION - 60 SERVICIOS; UNFLAVORED | D60: Micronized Creatine Powder - Optimum Nutrition - 60 servicios; unflavored | E60: 5 | F60: 8 | G60: Existencia actualizada
... A100: 3 - Suplementos | B100: 1212 | C100: JYM PLUS PRE-WORKOUT - JYM SUPPLEMENT SCIENCE - FRUIT PUNCH BLAST / TAMAÑO POR CONFIRMAR | D100: JYM Plus Pre-Workout - JYM Supplement Science - Fruit Punch Blast | E100: 9 | F100: 10 | G100: Existencia actualizada
A102: Nota paso 1: además, los 349 productos de Maquillaje que coinciden quedaron con el nombre exacto del listado "Inventario consolidado GV Makeup". Costos y precios no se tocaron.
A103: Nota paso 2: los 34 productos de Fajas que coinciden quedaron con el nombre en formato "Producto Talla Color" según el listado "Inventario fajas viernes 02 de octubre". Las Cinturillas repetidas en 2 bloques se sumaron por talla. Panty Negro M y S, Broche L (color por confirmar) y Faja tipo chaleco 3XS no salieron en el listado y quedaron en 0 con su nombre anterior.
...
